connection handler failed
Traceback (most recent call last):
  File "/home/pi/.local/lib/python3.9/site-packages/websockets/legacy/protocol.py", line 955, in transfer_data
    message = await self.read_message()
  File "/home/pi/.local/lib/python3.9/site-packages/websockets/legacy/protocol.py", line 1025, in read_message
    frame = await self.read_data_frame(max_size=self.max_size)
  File "/home/pi/.local/lib/python3.9/site-packages/websockets/legacy/protocol.py", line 1100, in read_data_frame
    frame = await self.read_frame(max_size)
  File "/home/pi/.local/lib/python3.9/site-packages/websockets/legacy/protocol.py", line 1157, in read_frame
    frame = await Frame.read(
  File "/home/pi/.local/lib/python3.9/site-packages/websockets/legacy/framing.py", line 68, in read
    data = await reader(2)
  File "/usr/lib/python3.9/asyncio/streams.py", line 721, in readexactly
    raise exceptions.IncompleteReadError(incomplete, n)
asyncio.exceptions.IncompleteReadError: 0 bytes read on a total of 2 expected bytes

The above exception was the direct cause of the following exception:

Traceback (most recent call last):
  File "/home/pi/.local/lib/python3.9/site-packages/websockets/legacy/server.py", line 245, in handler
    await self.ws_handler(self)
  File "/home/pi/.local/lib/python3.9/site-packages/websockets/legacy/server.py", line 1188, in _ws_handler
    return await cast(
  File "/home/pi/MomentCloud/chat_server.py", line 58, in handle_client
    async for message in websocket:
  File "/home/pi/.local/lib/python3.9/site-packages/websockets/legacy/protocol.py", line 494, in __aiter__
    yield await self.recv()
  File "/home/pi/.local/lib/python3.9/site-packages/websockets/legacy/protocol.py", line 564, in recv
    await self.ensure_open()
  File "/home/pi/.local/lib/python3.9/site-packages/websockets/legacy/protocol.py", line 931, in ensure_open
    raise self.connection_closed_exc()
websockets.exceptions.ConnectionClosedError: no close frame received or sent
connection handler failed
Traceback (most recent call last):
  File "/home/pi/.local/lib/python3.9/site-packages/websockets/legacy/protocol.py", line 955, in transfer_data
    message = await self.read_message()
  File "/home/pi/.local/lib/python3.9/site-packages/websockets/legacy/protocol.py", line 1025, in read_message
    frame = await self.read_data_frame(max_size=self.max_size)
  File "/home/pi/.local/lib/python3.9/site-packages/websockets/legacy/protocol.py", line 1100, in read_data_frame
    frame = await self.read_frame(max_size)
  File "/home/pi/.local/lib/python3.9/site-packages/websockets/legacy/protocol.py", line 1157, in read_frame
    frame = await Frame.read(
  File "/home/pi/.local/lib/python3.9/site-packages/websockets/legacy/framing.py", line 68, in read
    data = await reader(2)
  File "/usr/lib/python3.9/asyncio/streams.py", line 721, in readexactly
    raise exceptions.IncompleteReadError(incomplete, n)
asyncio.exceptions.IncompleteReadError: 0 bytes read on a total of 2 expected bytes

The above exception was the direct cause of the following exception:

Traceback (most recent call last):
  File "/home/pi/.local/lib/python3.9/site-packages/websockets/legacy/server.py", line 245, in handler
    await self.ws_handler(self)
  File "/home/pi/.local/lib/python3.9/site-packages/websockets/legacy/server.py", line 1188, in _ws_handler
    return await cast(
  File "/home/pi/MomentCloud/chat_server.py", line 58, in handle_client
    async for message in websocket:
  File "/home/pi/.local/lib/python3.9/site-packages/websockets/legacy/protocol.py", line 494, in __aiter__
    yield await self.recv()
  File "/home/pi/.local/lib/python3.9/site-packages/websockets/legacy/protocol.py", line 564, in recv
    await self.ensure_open()
  File "/home/pi/.local/lib/python3.9/site-packages/websockets/legacy/protocol.py", line 931, in ensure_open
    raise self.connection_closed_exc()
websockets.exceptions.ConnectionClosedError: no close frame received or sent
connection handler failed
Traceback (most recent call last):
  File "/home/pi/.local/lib/python3.9/site-packages/websockets/legacy/protocol.py", line 955, in transfer_data
    message = await self.read_message()
  File "/home/pi/.local/lib/python3.9/site-packages/websockets/legacy/protocol.py", line 1025, in read_message
    frame = await self.read_data_frame(max_size=self.max_size)
  File "/home/pi/.local/lib/python3.9/site-packages/websockets/legacy/protocol.py", line 1100, in read_data_frame
    frame = await self.read_frame(max_size)
  File "/home/pi/.local/lib/python3.9/site-packages/websockets/legacy/protocol.py", line 1157, in read_frame
    frame = await Frame.read(
  File "/home/pi/.local/lib/python3.9/site-packages/websockets/legacy/framing.py", line 68, in read
    data = await reader(2)
  File "/usr/lib/python3.9/asyncio/streams.py", line 721, in readexactly
    raise exceptions.IncompleteReadError(incomplete, n)
asyncio.exceptions.IncompleteReadError: 0 bytes read on a total of 2 expected bytes

The above exception was the direct cause of the following exception:

Traceback (most recent call last):
  File "/home/pi/.local/lib/python3.9/site-packages/websockets/legacy/server.py", line 245, in handler
    await self.ws_handler(self)
  File "/home/pi/.local/lib/python3.9/site-packages/websockets/legacy/server.py", line 1188, in _ws_handler
    return await cast(
  File "/home/pi/MomentCloud/chat_server.py", line 58, in handle_client
    async for message in websocket:
  File "/home/pi/.local/lib/python3.9/site-packages/websockets/legacy/protocol.py", line 494, in __aiter__
    yield await self.recv()
  File "/home/pi/.local/lib/python3.9/site-packages/websockets/legacy/protocol.py", line 564, in recv
    await self.ensure_open()
  File "/home/pi/.local/lib/python3.9/site-packages/websockets/legacy/protocol.py", line 931, in ensure_open
    raise self.connection_closed_exc()
websockets.exceptions.ConnectionClosedError: no close frame received or sent
connection handler failed
Traceback (most recent call last):
  File "/home/pi/.local/lib/python3.9/site-packages/websockets/legacy/protocol.py", line 955, in transfer_data
    message = await self.read_message()
  File "/home/pi/.local/lib/python3.9/site-packages/websockets/legacy/protocol.py", line 1025, in read_message
    frame = await self.read_data_frame(max_size=self.max_size)
  File "/home/pi/.local/lib/python3.9/site-packages/websockets/legacy/protocol.py", line 1100, in read_data_frame
    frame = await self.read_frame(max_size)
  File "/home/pi/.local/lib/python3.9/site-packages/websockets/legacy/protocol.py", line 1157, in read_frame
    frame = await Frame.read(
  File "/home/pi/.local/lib/python3.9/site-packages/websockets/legacy/framing.py", line 68, in read
    data = await reader(2)
  File "/usr/lib/python3.9/asyncio/streams.py", line 721, in readexactly
    raise exceptions.IncompleteReadError(incomplete, n)
asyncio.exceptions.IncompleteReadError: 0 bytes read on a total of 2 expected bytes

The above exception was the direct cause of the following exception:

Traceback (most recent call last):
  File "/home/pi/.local/lib/python3.9/site-packages/websockets/legacy/server.py", line 245, in handler
    await self.ws_handler(self)
  File "/home/pi/.local/lib/python3.9/site-packages/websockets/legacy/server.py", line 1188, in _ws_handler
    return await cast(
  File "/home/pi/MomentCloud/chat_server.py", line 58, in handle_client
    async for message in websocket:
  File "/home/pi/.local/lib/python3.9/site-packages/websockets/legacy/protocol.py", line 494, in __aiter__
    yield await self.recv()
  File "/home/pi/.local/lib/python3.9/site-packages/websockets/legacy/protocol.py", line 564, in recv
    await self.ensure_open()
  File "/home/pi/.local/lib/python3.9/site-packages/websockets/legacy/protocol.py", line 931, in ensure_open
    raise self.connection_closed_exc()
websockets.exceptions.ConnectionClosedError: no close frame received or sent
connection handler failed
Traceback (most recent call last):
  File "/home/pi/.local/lib/python3.9/site-packages/websockets/legacy/protocol.py", line 955, in transfer_data
    message = await self.read_message()
  File "/home/pi/.local/lib/python3.9/site-packages/websockets/legacy/protocol.py", line 1025, in read_message
    frame = await self.read_data_frame(max_size=self.max_size)
  File "/home/pi/.local/lib/python3.9/site-packages/websockets/legacy/protocol.py", line 1100, in read_data_frame
    frame = await self.read_frame(max_size)
  File "/home/pi/.local/lib/python3.9/site-packages/websockets/legacy/protocol.py", line 1157, in read_frame
    frame = await Frame.read(
  File "/home/pi/.local/lib/python3.9/site-packages/websockets/legacy/framing.py", line 68, in read
    data = await reader(2)
  File "/usr/lib/python3.9/asyncio/streams.py", line 721, in readexactly
    raise exceptions.IncompleteReadError(incomplete, n)
asyncio.exceptions.IncompleteReadError: 0 bytes read on a total of 2 expected bytes

The above exception was the direct cause of the following exception:

Traceback (most recent call last):
  File "/home/pi/.local/lib/python3.9/site-packages/websockets/legacy/server.py", line 245, in handler
    await self.ws_handler(self)
  File "/home/pi/.local/lib/python3.9/site-packages/websockets/legacy/server.py", line 1188, in _ws_handler
    return await cast(
  File "/home/pi/MomentCloud/chat_server.py", line 58, in handle_client
    async for message in websocket:
  File "/home/pi/.local/lib/python3.9/site-packages/websockets/legacy/protocol.py", line 494, in __aiter__
    yield await self.recv()
  File "/home/pi/.local/lib/python3.9/site-packages/websockets/legacy/protocol.py", line 564, in recv
    await self.ensure_open()
  File "/home/pi/.local/lib/python3.9/site-packages/websockets/legacy/protocol.py", line 931, in ensure_open
    raise self.connection_closed_exc()
websockets.exceptions.ConnectionClosedError: no close frame received or sent
connection handler failed
Traceback (most recent call last):
  File "/home/pi/.local/lib/python3.9/site-packages/websockets/legacy/protocol.py", line 955, in transfer_data
    message = await self.read_message()
  File "/home/pi/.local/lib/python3.9/site-packages/websockets/legacy/protocol.py", line 1025, in read_message
    frame = await self.read_data_frame(max_size=self.max_size)
  File "/home/pi/.local/lib/python3.9/site-packages/websockets/legacy/protocol.py", line 1100, in read_data_frame
    frame = await self.read_frame(max_size)
  File "/home/pi/.local/lib/python3.9/site-packages/websockets/legacy/protocol.py", line 1157, in read_frame
    frame = await Frame.read(
  File "/home/pi/.local/lib/python3.9/site-packages/websockets/legacy/framing.py", line 68, in read
    data = await reader(2)
  File "/usr/lib/python3.9/asyncio/streams.py", line 721, in readexactly
    raise exceptions.IncompleteReadError(incomplete, n)
asyncio.exceptions.IncompleteReadError: 0 bytes read on a total of 2 expected bytes

The above exception was the direct cause of the following exception:

Traceback (most recent call last):
  File "/home/pi/.local/lib/python3.9/site-packages/websockets/legacy/server.py", line 245, in handler
    await self.ws_handler(self)
  File "/home/pi/.local/lib/python3.9/site-packages/websockets/legacy/server.py", line 1188, in _ws_handler
    return await cast(
  File "/home/pi/MomentCloud/chat_server.py", line 58, in handle_client
  File "/home/pi/.local/lib/python3.9/site-packages/websockets/legacy/protocol.py", line 494, in __aiter__
    yield await self.recv()
  File "/home/pi/.local/lib/python3.9/site-packages/websockets/legacy/protocol.py", line 564, in recv
    await self.ensure_open()
  File "/home/pi/.local/lib/python3.9/site-packages/websockets/legacy/protocol.py", line 931, in ensure_open
    raise self.connection_closed_exc()
websockets.exceptions.ConnectionClosedError: no close frame received or sent
connection handler failed
Traceback (most recent call last):
  File "/home/pi/.local/lib/python3.9/site-packages/websockets/legacy/protocol.py", line 955, in transfer_data
    message = await self.read_message()
  File "/home/pi/.local/lib/python3.9/site-packages/websockets/legacy/protocol.py", line 1025, in read_message
    frame = await self.read_data_frame(max_size=self.max_size)
  File "/home/pi/.local/lib/python3.9/site-packages/websockets/legacy/protocol.py", line 1100, in read_data_frame
    frame = await self.read_frame(max_size)
  File "/home/pi/.local/lib/python3.9/site-packages/websockets/legacy/protocol.py", line 1157, in read_frame
    frame = await Frame.read(
  File "/home/pi/.local/lib/python3.9/site-packages/websockets/legacy/framing.py", line 68, in read
    data = await reader(2)
  File "/usr/lib/python3.9/asyncio/streams.py", line 721, in readexactly
    raise exceptions.IncompleteReadError(incomplete, n)
asyncio.exceptions.IncompleteReadError: 0 bytes read on a total of 2 expected bytes

The above exception was the direct cause of the following exception:

Traceback (most recent call last):
  File "/home/pi/.local/lib/python3.9/site-packages/websockets/legacy/server.py", line 245, in handler
    await self.ws_handler(self)
  File "/home/pi/.local/lib/python3.9/site-packages/websockets/legacy/server.py", line 1188, in _ws_handler
    return await cast(
  File "/home/pi/MomentCloud/chat_server.py", line 58, in handle_client
  File "/home/pi/.local/lib/python3.9/site-packages/websockets/legacy/protocol.py", line 494, in __aiter__
    yield await self.recv()
  File "/home/pi/.local/lib/python3.9/site-packages/websockets/legacy/protocol.py", line 564, in recv
    await self.ensure_open()
  File "/home/pi/.local/lib/python3.9/site-packages/websockets/legacy/protocol.py", line 931, in ensure_open
    raise self.connection_closed_exc()
websockets.exceptions.ConnectionClosedError: no close frame received or sent
connection handler failed
Traceback (most recent call last):
  File "/home/pi/.local/lib/python3.9/site-packages/websockets/legacy/protocol.py", line 955, in transfer_data
    message = await self.read_message()
  File "/home/pi/.local/lib/python3.9/site-packages/websockets/legacy/protocol.py", line 1025, in read_message
    frame = await self.read_data_frame(max_size=self.max_size)
  File "/home/pi/.local/lib/python3.9/site-packages/websockets/legacy/protocol.py", line 1100, in read_data_frame
    frame = await self.read_frame(max_size)
  File "/home/pi/.local/lib/python3.9/site-packages/websockets/legacy/protocol.py", line 1157, in read_frame
    frame = await Frame.read(
  File "/home/pi/.local/lib/python3.9/site-packages/websockets/legacy/framing.py", line 68, in read
    data = await reader(2)
  File "/usr/lib/python3.9/asyncio/streams.py", line 721, in readexactly
    raise exceptions.IncompleteReadError(incomplete, n)
asyncio.exceptions.IncompleteReadError: 0 bytes read on a total of 2 expected bytes

The above exception was the direct cause of the following exception:

Traceback (most recent call last):
  File "/home/pi/.local/lib/python3.9/site-packages/websockets/legacy/server.py", line 245, in handler
    await self.ws_handler(self)
  File "/home/pi/.local/lib/python3.9/site-packages/websockets/legacy/server.py", line 1188, in _ws_handler
    return await cast(
  File "/home/pi/MomentCloud/chat_server.py", line 58, in handle_client
  File "/home/pi/.local/lib/python3.9/site-packages/websockets/legacy/protocol.py", line 494, in __aiter__
    yield await self.recv()
  File "/home/pi/.local/lib/python3.9/site-packages/websockets/legacy/protocol.py", line 564, in recv
    await self.ensure_open()
  File "/home/pi/.local/lib/python3.9/site-packages/websockets/legacy/protocol.py", line 931, in ensure_open
    raise self.connection_closed_exc()
websockets.exceptions.ConnectionClosedError: no close frame received or sent
connection handler failed
Traceback (most recent call last):
  File "/home/pi/.local/lib/python3.9/site-packages/websockets/legacy/protocol.py", line 955, in transfer_data
    message = await self.read_message()
  File "/home/pi/.local/lib/python3.9/site-packages/websockets/legacy/protocol.py", line 1025, in read_message
    frame = await self.read_data_frame(max_size=self.max_size)
  File "/home/pi/.local/lib/python3.9/site-packages/websockets/legacy/protocol.py", line 1100, in read_data_frame
    frame = await self.read_frame(max_size)
  File "/home/pi/.local/lib/python3.9/site-packages/websockets/legacy/protocol.py", line 1157, in read_frame
    frame = await Frame.read(
  File "/home/pi/.local/lib/python3.9/site-packages/websockets/legacy/framing.py", line 68, in read
    data = await reader(2)
  File "/usr/lib/python3.9/asyncio/streams.py", line 721, in readexactly
    raise exceptions.IncompleteReadError(incomplete, n)
asyncio.exceptions.IncompleteReadError: 0 bytes read on a total of 2 expected bytes

The above exception was the direct cause of the following exception:

Traceback (most recent call last):
  File "/home/pi/.local/lib/python3.9/site-packages/websockets/legacy/server.py", line 245, in handler
    await self.ws_handler(self)
  File "/home/pi/.local/lib/python3.9/site-packages/websockets/legacy/server.py", line 1188, in _ws_handler
    return await cast(
  File "/home/pi/MomentCloud/chat_server.py", line 58, in handle_client
  File "/home/pi/.local/lib/python3.9/site-packages/websockets/legacy/protocol.py", line 494, in __aiter__
    yield await self.recv()
  File "/home/pi/.local/lib/python3.9/site-packages/websockets/legacy/protocol.py", line 564, in recv
    await self.ensure_open()
  File "/home/pi/.local/lib/python3.9/site-packages/websockets/legacy/protocol.py", line 931, in ensure_open
    raise self.connection_closed_exc()
websockets.exceptions.ConnectionClosedError: no close frame received or sent
